File: Röntgen/KEN009_XRD_40_85deg.xrdml
<?xml version="1.0" encoding="UTF-8"?>
<xrdMeasurements xmlns="http://www.xrdml.com/XRDMeasurement/1.5" xmlns:xsi="http://www.w3.org/2001/XMLSchema-instance" xsi:schemaLocation="http://www.xrdml.com/XRDMeasurement/1.5 http://www.xrdml.com/XRDMeasurement/1.5/XRDMeasurement.xsd" status="Completed">
	<comment>
		<entry>Configuration=MRD 2016, Owner=hydrogen, Creation date=09-Dec-16 19:44:12</entry>
		<entry>Goniometer=PW3050/65 (Theta/2Theta); Minimum step size 2Theta:0.0001; Minimum step size Omega:0.0001</entry>
		<entry>Sample stage=MRD Cradle; Minimum step size Phi:0.01; Minimum step size Chi:0.01; Minimum step size X:0.01; Minimum step size Y:0.01; Minimum step size Z:0.001</entry>
		<entry>Diffractometer system=XPERT-PRO</entry>
		<entry>Measurement program=Manual, Owner=hydrogen, Creation date=30-Jan-20 12:54:00</entry>
		<entry>Fine Calibration Offset for 2Theta = 0.0048 deg</entry>
		<entry>Fine Calibration Offset for Omega = 0.0080 deg</entry>
	</comment>
	<sample type="To be analyzed">
		<id></id>
		<name></name>
		<preparedBy></preparedBy>
	</sample>
	<xrdMeasurement measurementType="Scan" status="Completed" sampleMode="Reflection">
		<comment>
			<entry>PHD Lower Level = 5.63 (keV), PHD Upper Level = 12.88 (keV)</entry>
		</comment>
		<usedWavelength intended="K-Alpha 1">
			<kAlpha1 unit="Angstrom">1.5405940</kAlpha1>
			<kAlpha2 unit="Angstrom">1.5444080</kAlpha2>
			<kBeta unit="Angstrom">1.3922500</kBeta>
			<ratioKAlpha2KAlpha1>0.5200</ratioKAlpha2KAlpha1>
		</usedWavelength>
		<incidentBeamPath>
			<radius unit="mm">320.00</radius>
			<xRayTube id="1010048" name="Empyrean Cu LFF HR (9430 033 7310x) DK164548">
				<tension unit="kV">45</tension>
				<current unit="mA">40</current>
				<anodeMaterial>Cu</anodeMaterial>
				<focus type="Line">
					<length unit="mm">12.0</length>
					<width unit="mm">0.4</width>
					<takeOffAngle unit="deg">3.4</takeOffAngle>
				</focus>
			</xRayTube>
			<xRayMirror id="27010001" name="Inc. Beam Cu W/Si (parabolic MRD)" hybrid="false">
				<crystal type="Graded" shape="Parabolic">W/Si</crystal>
				<acceptanceAngle unit="deg">0.800</acceptanceAngle>
				<length unit="mm">60.0</length>
			</xRayMirror>
			<sollerSlit id="21010001" name="Soller slits 0.02 rad.">
				<opening unit="rad">0.0200</opening>
			</sollerSlit>
			<divergenceSlit id="22010007" name="Fixed slit 1/8°" xsi:type="fixedDivergenceSlitType">
				<distanceToSample unit="mm">220.00</distanceToSample>
				<height unit="mm">0.19</height>
			</divergenceSlit>
			<beamAttenuator id="26010002" name="Beam attenuator Cu 0.1 mm" xsi:type="intensitySwitchedBeamAttenuatorType">
				<factor>119.20</factor>
				<material>Cu</material>
				<activateLevel unit="counts per second">500000</activateLevel>
				<deactivateLevel unit="counts per second">400000</deactivateLevel>
			</beamAttenuator>
		</incidentBeamPath>
		<sampleOffset>
			<position axis="2Theta" unit="deg">0.0000</position>
			<position axis="Omega" unit="deg">-0.1476</position>
		</sampleOffset>
		<diffractedBeamPath>
			<radius unit="mm">320.00</radius>
			<parallelPlateCollimator id="25010001" name="Parallel plate collimator 0.27°">
				<opening unit="deg">0.27</opening>
			</parallelPlateCollimator>
			<detector id="7010011" name="Proportional detector Xe" xsi:type="pointDetectorType">
				<phd>
					<lowerLevel unit="%">35.0</lowerLevel>
					<upperLevel unit="%">80.0</upperLevel>
				</phd>
			</detector>
		</diffractedBeamPath>
		<scan appendNumber="0" mode="Continuous" scanAxis="2Theta-Omega" status="Completed">
			<header>
				<startTimeStamp>2020-01-30T13:40:22+00:00</startTimeStamp>
				<endTimeStamp>2020-01-30T14:02:55+00:00</endTimeStamp>
				<author>
					<name>X-ray User</name>
				</author>
				<source>
					<applicationSoftware version="5.2a">Data Collector</applicationSoftware>
					<instrumentControlSoftware version="2.2B 20140619">XPERT-PRO</instrumentControlSoftware>
					<instrumentID>0000000011014754</instrumentID>
				</source>
			</header>
			<scanAxisCenter>
				<position axis="2Theta" unit="deg">62.5000</position>
				<position axis="Omega" unit="deg">31.2500</position>
			</scanAxisCenter>
			<reflection>
				<hkl>
					<h>0</h>
					<k>0</k>
					<l>0</l>
				</hkl>
			</reflection>
			<dataPoints>
				<positions axis="2Theta" unit="deg">
					<startPosition>40.0200</startPosition>
					<endPosition>84.9800</endPosition>
				</positions>
				<positions axis="Omega" unit="deg">
					<startPosition>20.0100</startPosition>
					<endPosition>42.4900</endPosition>
				</positions>
				<positions axis="Phi" unit="deg">
					<commonPosition>0.00</commonPosition>
				</positions>
				<positions axis="Chi" unit="deg">
					<commonPosition>0.00</commonPosition>
				</positions>
				<positions axis="X" unit="mm">
					<commonPosition>0.00</commonPosition>
				</positions>
				<positions axis="Y" unit="mm">
					<commonPosition>0.00</commonPosition>
				</positions>
				<positions axis="Z" unit="mm">
					<commonPosition>6.760</commonPosition>
				</positions>
				<beamAttenuationFactors>1.00 1.00 1.00 1.00 1.00 1.00 1.00 1.00 1.00 1.00 1.00 1.00 1.00 1.00 1.00 1.00 1.00 1.00 1.00 1.00 1.00 1.00 1.00 1.00 1.00 1.00 1.00 1.00 1.00 1.00 1.00 1.00 1.00 1.00 1.00 1.00 1.00 1.00 1.00 1.00 1.00 1.00 1.00 1.00 1.00 1.00 1.00 1.00 1.00 1.00 1.00 1.00 1.00 1.00 1.00 1.00 1.00 1.00 1.00 1.00 1.00 1.00 1.00 1.00 1.00 1.00 1.00 1.00 1.00 1.00 1.00 1.00 1.00 1.00 1.00 1.00 1.00 1.00 1.00 1.00 1.00 1.00 1.00 1.00 1.00 1.00 1.00 1.00 1.00 1.00 1.00 1.00 1.00 1.00 1.00 1.00 1.00 1.00 1.00 1.00 1.00 1.00 1.00 1.00 1.00 1.00 1.00 1.00 1.00 1.00 1.00 1.00 1.00 1.00 1.00 1.00 1.00 1.00 1.00 1.00 1.00 1.00 1.00 1.00 1.00 1.00 1.00 1.00 1.00 1.00 1.00 1.00 1.00 1.00 1.00 1.00 1.00 1.00 1.00 1.00 1.00 1.00 1.00 1.00 1.00 1.00 1.00 1.00 1.00 1.00 1.00 1.00 1.00 1.00 1.00 1.00 1.00 1.00 1.00 1.00 1.00 1.00 1.00 1.00 1.00 1.00 1.00 1.00 1.00 1.00 1.00 1.00 1.00 1.00 1.00 1.00 1.00 1.00 1.00 1.00 1.00 1.00 1.00 1.00 1.00 1.00 1.00 1.00 1.00 1.00 1.00 1.00 1.00 1.00 1.00 1.00 1.00 1.00 1.00 1.00 1.00 1.00 1.00 1.00 1.00 1.00 1.00 1.00 1.00 1.00 1.00 1.00 1.00 1.00 1.00 1.00 1.00 1.00 1.00 1.00 1.00 1.00 1.00 1.00 1.00 1.00 1.00 1.00 1.00 1.00 1.00 1.00 1.00 1.00 1.00 1.00 1.00 1.00 1.00 1.00 1.00 1.00 1.00 1.00 1.00 1.00 1.00 1.00 1.00 1.00 1.00 1.00 1.00 1.00 1.00 1.00 1.00 1.00 1.00 1.00 1.00 1.00 1.00 1.00 1.00 1.00 1.00 1.00 1.00 1.00 1.00 1.00 1.00 1.00 1.00 1.00 1.00 1.00 1.00 1.00 1.00 1.00 1.00 1.00 1.00 1.00 1.00 1.00 1.00 1.00 1.00 1.00 1.00 1.00 1.00 1.00 1.00 1.00 1.00 1.00 1.00 1.00 1.00 1.00 1.00 1.00 1.00 1.00 1.00 1.00 1.00 1.00 1.00 1.00 1.00 1.00 1.00 1.00 1.00 1.00 1.00 1.00 1.00 1.00 1.00 1.00 1.00 1.00 1.00 1.00 1.00 1.00 1.00 1.00 1.00 1.00 1.00 1.00 1.00 1.00 1.00 1.00 1.00 1.00 1.00 1.00 1.00 1.00 1.00 1.00 1.00 1.00 1.00 1.00 1.00 1.00 1.00 1.00 1.00 1.00 1.00 1.00 1.00 1.00 1.00 1.00 1.00 1.00 1.00 1.00 1.00 1.00 1.00 1.00 1.00 1.00 1.00 1.00 1.00 1.00 1.00 1.00 1.00 1.00 1.00 1.00 1.00 1.00 1.00 1.00 1.00 1.00 1.00 1.00 1.00 1.00 1.00 1.00 1.00 1.00 1.00 1.00 1.00 1.00 1.00 1.00 1.00 1.00 1.00 1.00 1.00 1.00 1.00 1.00 1.00 1.00 1.00 1.00 1.00 1.00 1.00 1.00 1.00 1.00 1.00 1.00 1.00 1.00 1.00 1.00 1.00 1.00 1.00 1.00 1.00 1.00 1.00 1.00 1.00 1.00 1.00 1.00 1.00 1.00 1.00 1.00 1.00 1.00 1.00 1.00 1.00 1.00 1.00 1.00 1.00 1.00 1.00 1.00 1.00 1.00 1.00 1.00 1.00 1.00 1.00 1.00 1.00 1.00 1.00 1.00 1.00 1.00 1.00 1.00 1.00 1.00 1.00 1.00 1.00 1.00 1.00 1.00 1.00 1.00 1.00 1.00 1.00 1.00 1.00 1.00 1.00 1.00 1.00 1.00 1.00 1.00 1.00 1.00 1.00 1.00 1.00 1.00 1.00 1.00 1.00 1.00 1.00 1.00 1.00 1.00 1.00 1.00 1.00 1.00 1.00 1.00 1.00 1.00 1.00 1.00 1.00 1.00 1.00 1.00 1.00 1.00 1.00 1.00 1.00 1.00 1.00 1.00 1.00 1.00 1.00 1.00 1.00 1.00 1.00 1.00 1.00 1.00 1.00 1.00 1.00 1.00 1.00 1.00 1.00 1.00 1.00 1.00 1.00 1.00 1.00 1.00 1.00 1.00 1.00 1.00 1.00 1.00 1.00 1.00 1.00 1.00 1.00 1.00 1.00 1.00 1.00 1.00 1.00 1.00 1.00 1.00 1.00 1.00 1.00 1.00 1.00 1.00 1.00 1.00 1.00 1.00 1.00 1.00 1.00 1.00 1.00 1.00 1.00 1.00 1.00 1.00 1.00 1.00 1.00 1.00 1.00 1.00 1.00 1.00 1.00 1.00 1.00 1.00 1.00 1.00 1.00 1.00 1.00 1.00 1.00 1.00 1.00 1.00 1.00 1.00 1.00 1.00 1.00 1.00 1.00 1.00 1.00 1.00 1.00 1.00 1.00 1.00 1.00 1.00 1.00 1.00 1.00 1.00 1.00 1.00 1.00 1.00 1.00 1.00 1.00 1.00 1.00 1.00 1.00 1.00 1.00 1.00 1.00 1.00 1.00 1.00 1.00 1.00 1.00 1.00 1.00 1.00 1.00 1.00 1.00 1.00 1.00 1.00 1.00 1.00 1.00 1.00 1.00 1.00 1.00 1.00 1.00 1.00 1.00 1.00 1.00 1.00 1.00 1.00 1.00 1.00 1.00 1.00 1.00 1.00 1.00 1.00 1.00 1.00 1.00 1.00 1.00 1.00 1.00 1.00 1.00 1.00 1.00 1.00 1.00 1.00 1.00 1.00 1.00 1.00 1.00 1.00 1.00 1.00 1.00 1.00 1.00 1.00 1.00 1.00 1.00 1.00 1.00 1.00 1.00 1.00 1.00 119.20 119.20 119.20 1.00 1.00 119.20 119.20 1.00 1.00 1.00 1.00 1.00 1.00 1.00 1.00 1.00 1.00 1.00 1.00 1.00 1.00 1.00 1.00 1.00 1.00 1.00 1.00 1.00 1.00 1.00 1.00 1.00 1.00 1.00 1.00 1.00 1.00 1.00 1.00 1.00 1.00 1.00 1.00 1.00 1.00 1.00 1.00 1.00 1.00 1.00 1.00 1.00 1.00 1.00 1.00 1.00 1.00 1.00 1.00 1.00 1.00 1.00 1.00 1.00 1.00 1.00 1.00 1.00 1.00 1.00 1.00 1.00 1.00 1.00 1.00 1.00 1.00 1.00 1.00 1.00 1.00 1.00 1.00 1.00 1.00 1.00 1.00 1.00 1.00 1.00 1.00 1.00 1.00 1.00 1.00 1.00 1.00 1.00 1.00 1.00 1.00 1.00 1.00 1.00 1.00 1.00 1.00 1.00 1.00 1.00 1.00 1.00 1.00 1.00 1.00 1.00 1.00 1.00 1.00 1.00 1.00 1.00 1.00 1.00 1.00 1.00 1.00 1.00 1.00 1.00 1.00 1.00 1.00 1.00 1.00 1.00 1.00 1.00 1.00 1.00 1.00 1.00 1.00 1.00 1.00 1.00 1.00 1.00 1.00 1.00 1.00 1.00 1.00 1.00 1.00 1.00 1.00 1.00 1.00 1.00 1.00 1.00 1.00 1.00 1.00 1.00 1.00 1.00 1.00 1.00 1.00 1.00 1.00 1.00 1.00 1.00 1.00 1.00 1.00 1.00 1.00 1.00 1.00 1.00 1.00 1.00 1.00 1.00 1.00 1.00 1.00 1.00 1.00 1.00 1.00 1.00 1.00 1.00 1.00 1.00 1.00 1.00 1.00 1.00 1.00 1.00 1.00 1.00 1.00 1.00 1.00 1.00 1.00 1.00 1.00 1.00 1.00 1.00 1.00 1.00 1.00 1.00 1.00 1.00 1.00 1.00 1.00 1.00 1.00 1.00 1.00 1.00 1.00 1.00 1.00 1.00 1.00 1.00 1.00 1.00 1.00 1.00 1.00 1.00 1.00 1.00 1.00 1.00 1.00 1.00 1.00 1.00 1.00 1.00 1.00 1.00 1.00 1.00 1.00 1.00 1.00 1.00 1.00 1.00 1.00 1.00 1.00 1.00 1.00 1.00 1.00 1.00 1.00 1.00 1.00 1.00 1.00 1.00 1.00 1.00 1.00 1.00 1.00 1.00 1.00 1.00 1.00 1.00 1.00 1.00 1.00 1.00 1.00 1.00 1.00 1.00 1.00 1.00 1.00 1.00 1.00 1.00 1.00 1.00 1.00 1.00 1.00 1.00 1.00 1.00 1.00 1.00 1.00 1.00 1.00 1.00 1.00 1.00 1.00 1.00 1.00 1.00 1.00 1.00 1.00 1.00 1.00 1.00 1.00 1.00 1.00 1.00 1.00 1.00 1.00 1.00 1.00 1.00 1.00 1.00 1.00 1.00 1.00 1.00 1.00 1.00 1.00 1.00 1.00 1.00 1.00 1.00 1.00 1.00 1.00 1.00 1.00 1.00 1.00 1.00 1.00 1.00 1.00 1.00 1.00 1.00 1.00 1.00 1.00 1.00 1.00 1.00 1.00 1.00 1.00 1.00 1.00 1.00 1.00 1.00 1.00 1.00 1.00 1.00 1.00 1.00 1.00 1.00 1.00 1.00 1.00 1.00 1.00 1.00 1.00 1.00 1.00 1.00</beamAttenuationFactors>
				<commonCountingTime unit="seconds">1.00</commonCountingTime>
				<intensities unit="counts">45 47 35 53 53 51 30 53 53 40 37 45 46 40 49 44 44 48 39 41 40 37 57 48 32 33 42 47 31 42 53 38 44 38 49 36 37 41 30 48 46 36 44 36 41 38 36 42 44 37 42 38 43 51 37 39 39 47 41 53 36 35 48 51 48 43 35 46 38 40 33 41 39 44 35 50 34 39 47 43 35 36 47 41 34 38 37 46 37 46 51 38 32 45 30 42 50 38 27 53 30 41 44 41 53 45 50 42 56 64 62 79 96 126 123 137 146 158 139 165 133 116 102 82 85 56 53 62 50 51 48 40 40 41 48 43 47 45 40 31 37 28 34 37 40 36 47 40 29 31 33 28 37 42 44 49 37 28 29 40 51 35 40 30 27 25 33 34 28 41 38 37 43 41 46 43 35 33 39 22 39 36 43 38 25 37 30 42 25 28 34 33 32 34 46 39 28 29 32 34 38 41 22 26 44 31 36 39 29 38 26 35 31 36 35 25 39 40 36 32 35 37 41 51 29 33 34 35 24 41 35 44 47 35 29 30 32 24 34 34 37 27 36 26 25 28 26 36 33 26 30 34 42 37 30 28 25 45 37 41 24 40 38 31 41 34 26 36 28 31 32 33 37 36 37 27 30 29 29 36 42 36 33 31 45 36 28 37 32 31 31 37 23 29 40 39 34 29 25 29 42 28 29 27 42 32 38 30 31 37 25 37 26 28 27 27 36 28 33 28 43 30 32 33 41 35 37 44 43 37 36 30 26 35 29 29 30 41 32 29 31 36 28 39 40 34 45 36 34 25 33 41 28 34 38 40 41 27 34 29 34 46 54 42 42 46 32 43 49 43 39 46 38 40 47 79 83 55 40 43 41 34 35 36 47 36 47 44 44 30 46 22 34 51 51 60 69 48 38 44 37 31 32 44 45 50 57 92 86 63 59 53 57 63 54 78 99 209 334 261 123 57 55 56 42 57 57 54 54 56 52 44 43 44 40 41 36 46 47 52 65 75 65 49 62 40 47 41 46 45 48 41 39 40 37 38 42 43 32 54 41 41 49 42 48 47 41 37 35 42 56 42 32 26 34 36 40 35 52 39 58 32 42 51 52 39 42 50 42 39 41 48 41 38 51 48 43 52 46 41 53 46 58 40 50 51 42 38 48 44 45 40 49 44 40 58 52 52 50 58 47 51 56 50 57 62 79 71 79 81 69 80 85 68 98 108 92 113 191 395 1050 2445 2184 862 393 334 444 828 938 745 424 247 173 161 182 150 119 96 96 100 100 104 104 96 101 97 82 103 98 82 99 84 95 126 124 110 111 135 102 102 121 103 121 128 115 94 126 108 107 101 107 118 106 122 117 112 122 115 107 125 98 119 111 129 134 113 134 127 117 106 125 101 128 159 117 150 120 135 163 137 144 141 143 163 157 166 166 174 173 176 174 177 178 206 195 213 213 245 242 317 327 415 564 827 1525 3535 6046 5032 3186 2697 1994 1099 809 630 513 440 449 473 583 914 1370 1156 833 673 545 505 468 466 439 445 427 425 429 433 569 541 670 701 654 666 659 661 689 732 772 838 864 903 965 1022 1052 1105 1127 1193 1230 1273 1438 1473 1490 1595 1624 1832 1913 1979 2103 2324 2304 2549 2732 2954 3064 3531 3932 4297 4849 5554 7193 10297 15513 20362 21683 20866 23638 31886 54422 120759 477242 2005302 1909465 443782 178646 384576 1081502 843578 210122 66194 37441 25786 19592 15719 12892 10934 9582 8646 7872 6900 6326 5901 5587 5146 5098 4688 4343 4300 3998 3858 3810 3577 3432 2982 2851 2775 2599 2407 2398 2270 2172 2099 2066 1893 1805 1812 1702 1625 1593 1544 1408 1347 1288 1208 1119 1147 1087 1052 949 974 904 907 774 847 731 719 654 652 661 677 566 533 511 533 464 457 438 411 398 396 407 357 378 353 391 313 318 309 269 279 327 258 222 258 249 232 235 221 203 213 205 194 195 169 185 193 170 185 155 163 146 175 148 150 151 143 158 124 117 140 132 118 117 103 103 110 105 114 90 127 106 100 96 111 96 89 94 91 96 115 88 104 99 98 95 89 85 92 106 125 140 125 102 103 169 173 123 100 74 105 110 78 77 72 67 73 74 80 80 70 85 81 72 65 77 72 77 85 82 99 101 87 84 96 63 76 59 71 69 59 43 66 64 52 53 51 49 59 40 64 39 46 40 50 46 58 46 47 45 46 43 57 53 28 53 49 41 56 44 35 34 43 55 46 41 43 48 40 42 47 40 40 43 36 50 35 33 43 36 44 41 42 39 38 26 34 43 38 40 36 34 29 48 35 30 22 31 54 35 39 34 37 35 46 40 34 40 31 24 38 24 31 38 30 30 35 30 35 30 27 32 36 41 33 29 31 23 39 28 28 33 36 36 30 43 28 43 26 29 30 36 34 33 40 23 23 25 36 24 30 32 22 40 25 29 21 35 30 27 14 21 31 28 25 33 30 25 35 35 29 38 32 34 38 32 46 33 34 43 35 28 32 24 26 32 28 23 19 29 31 19 28 30 23 34 27 25 31 30 40 26 34 27 36 26 29 23 23 23 17 13 33 25 26 25 29 26 18 25 27 23 23 25 31 22 33 29 20 35 19 31 21 17 17 35 16 6 27 20</intensities>
			</dataPoints>
		</scan>
	</xrdMeasurement>
</xrdMeasurements>